<?xml version="1.0"?>
<sdf version="1.9">
  <model name="orne_boxF">

    <link name="base_footprint">

      <inertial>
        <pose>0.091102 0 0.176713 0 -0 0</pose>
        <mass>25.4</mass>
        <inertia>
          <ixx>1.22486</ixx>
          <ixy>0</ixy>
          <ixz>0.016878</ixz>
          <iyy>3.58311</iyy>
          <iyz>0</iyz>
          <izz>3.93825</izz>
        </inertia>
      </inertial>

      <collision name="base_link_collision">
        <pose>0.09 0 0.1715 0 -0 0</pose>
        <geometry>
          <box>
            <size>0.4 0.404 0.202</size>
          </box>
        </geometry>
        <surface>
          <contact><ode/></contact>
          <friction>
            <ode>
              <mu>0.8</mu>
              <mu2>0.8</mu2>
            </ode>
          </friction>
        </surface>
      </collision>

      <collision name="base_link_collision_1">
        <pose>0.36125 0 0.2625 0 -0 0</pose>
        <geometry>
          <box>
            <size>0.1425 0.404 0.02</size>
          </box>
        </geometry>
        <surface>
          <contact><ode/></contact>
          <friction>
            <ode>
              <mu>0.8</mu>
              <mu2>0.8</mu2>
            </ode>
          </friction>
        </surface>
      </collision>

      <collision name="base_link_collision_2">
        <pose>0.35625 0 0.156 0 -0 0</pose>
        <geometry>
          <box>
            <size>0.1325 0.404 0.02</size>
          </box>
        </geometry>
        <surface>
          <contact><ode/></contact>
          <friction>
            <ode>
              <mu>0.8</mu>
              <mu2>0.8</mu2>
            </ode>
          </friction>
        </surface>
      </collision>

      <collision name="base_link_collision_3">
        <pose>-0.12 0 0.4815 0 -0 0</pose>
        <geometry>
          <box>
            <size>0.02 0.404 0.822</size>
          </box>
        </geometry>
        <surface>
          <contact><ode/></contact>
          <friction>
            <ode>
              <mu>0.8</mu>
              <mu2>0.8</mu2>
            </ode>
          </friction>
        </surface>
      </collision>

      <visual name="base_link_visual">
        <pose>0.09 0 0.1715 0 -0 0</pose>
        <geometry>
          <box>
            <size>0.4 0.404 0.202</size>
          </box>
        </geometry>
        <material>
          <ambient>1.0 0.5 0.0 1</ambient>
          <diffuse>1.0 0.5 0.0 1</diffuse>
          <specular>0.1 0.1 0.1 1</specular>
          <emissive>0 0 0 1</emissive>
        </material>
      </visual>

      <visual name="base_link_visual_1">
        <pose>0.36125 0 0.2625 0 -0 0</pose>
        <geometry>
          <box>
            <size>0.1425 0.404 0.02</size>
          </box>
        </geometry>
        <material>
          <ambient>1.0 0.5 0.0 1</ambient>
          <diffuse>1.0 0.5 0.0 1</diffuse>
          <specular>0.1 0.1 0.1 1</specular>
          <emissive>0 0 0 1</emissive>
        </material>
      </visual>

      <visual name="base_link_visual_2">
        <pose>0.35625 0 0.156 0 -0 0</pose>
        <geometry>
          <box>
            <size>0.1325 0.404 0.02</size>
          </box>
        </geometry>
        <material>
          <ambient>1.0 0.5 0.0 1</ambient>
          <diffuse>1.0 0.5 0.0 1</diffuse>
          <specular>0.1 0.1 0.1 1</specular>
          <emissive>0 0 0 1</emissive>
        </material>
      </visual>

      <visual name="base_link_visual_3">
        <pose>-0.12 0 0.4815 0 -0 0</pose>
        <geometry>
          <box>
            <size>0.02 0.404 0.822</size>
          </box>
        </geometry>
        <material>
          <ambient>1.0 0.5 0.0 1</ambient>
          <diffuse>1.0 0.5 0.0 1</diffuse>
          <specular>0.1 0.1 0.1 1</specular>
          <emissive>0 0 0 1</emissive>
        </material>
      </visual>

    </link>

    <joint name="rsf_x001_joint" type="fixed">
      <pose relative_to="base_footprint">0.3 0 0.35 0 -0 0</pose>
      <parent>base_footprint</parent>
      <child>rsf_x001_link</child>
    </joint>

    <link name="rsf_x001_link">
      <pose relative_to="rsf_x001_joint">0 0 0 0 -0 0</pose>

      <inertial>
        <pose>-0.1 0 0.0053 0 -0 0</pose>
        <mass>3.0</mass>
        <inertia>
          <ixx>0.001</ixx>
          <ixy>0</ixy>
          <ixz>0</ixz>
          <iyy>0.001</iyy>
          <iyz>0</iyz>
          <izz>0.001</izz>
        </inertia>
      </inertial>

      <collision name="rsf_x001_collision">
        <pose>-0.1 0 0.0053 0 -0 0</pose>
        <geometry>
          <box>
            <size>0.2112 0.147 0.1656</size>
          </box>
        </geometry>
        <surface>
          <contact><ode/></contact>
          <friction><ode/></friction>
        </surface>
      </collision>

      <visual name="rsf_x001_visual">
        <pose>-0.0296 0 -0.0775 1.5708 -0 1.5708</pose>
        <geometry>
          <mesh>
            <scale>0.001 0.001 0.001</scale>
            <uri>package://rsf_simulator/models/orne_boxF/meshes/RSF-X001.stl</uri>
          </mesh>
        </geometry>
        <material>
          <ambient>0.2 0.2 0.2 1</ambient>
          <diffuse>0.2 0.2 0.2 1</diffuse>
          <specular>0.1 0.1 0.1 1</specular>
          <emissive>0 0 0 1</emissive>
        </material>
      </visual>

      <sensor name="rsf_hokuyo3d" type="gpu_lidar">
        <topic>/rsf/hokuyo3d</topic>
        <update_rate>20</update_rate>
        <lidar>
          <scan>
            <horizontal>
              <samples>36</samples>
              <resolution>1</resolution>
              <min_angle>-1.8326</min_angle>
              <max_angle>1.8326</max_angle>
            </horizontal>
            <vertical>
              <samples>74</samples>
              <resolution>1</resolution>
              <min_angle>-0.0873</min_angle>
              <max_angle>0.6109</max_angle>
            </vertical>
          </scan>
          <range>
            <min>0.3</min>
            <max>35.0</max>
            <resolution>0.01</resolution>
          </range>
        </lidar>
        <visualize>true</visualize>
        <pose>0 0 0 0 -0 0</pose>
        <ignition_frame_id>rsf_hokuyo3d</ignition_frame_id>
        <always_on>1</always_on>
      </sensor>

      <sensor name="rsf_imu" type="imu">
        <topic>/rsf/imu</topic>
        <update_rate>1000</update_rate>
        <always_on>1</always_on>
        <visualize>0</visualize>
        <pose>-0.1 0 -0.02 0 -0 0</pose>
        <ignition_frame_id>rsf_hokuyo3d_imu</ignition_frame_id>
      </sensor>

      <sensor name="rsf_gnss" type="navsat">
        <topic>/rsf/nav_sat_fix</topic>
        <update_rate>1</update_rate>
        <always_on>1</always_on>
        <pose>-0.1 0 0.085 0 -0 0</pose>
        <ignition_frame_id>rsf_gnss</ignition_frame_id>
      </sensor>

    </link>

    <joint name="rsf_hokuyo3d_joint" type="fixed">
      <pose relative_to="rsf_x001_link">0 0 0 0 -0 0</pose>
      <parent>rsf_x001_link</parent>
      <child>rsf_hokuyo3d</child>
    </joint>

    <link name="rsf_hokuyo3d">
      <pose relative_to="rsf_hokuyo3d_joint">0 0 0 0 -0 0</pose>
      <inertial>
        <mass>0.0001</mass>
        <inertia>
          <ixx>1e-9</ixx>
          <ixy>0</ixy>
          <ixz>0</ixz>
          <iyy>1e-9</iyy>
          <iyz>0</iyz>
          <izz>1e-9</izz>
        </inertia>
      </inertial>
    </link>

    <joint name="left_caster_ball_joint" type="ball">
      <pose relative_to="base_footprint">0.392 0.15 0.05 0 -0 0</pose>
      <parent>base_footprint</parent>
      <child>left_caster_wheel_link</child>
    </joint>

    <link name="left_caster_wheel_link">
      <pose relative_to="left_caster_ball_joint">0 0 0 1.5708 0 0</pose>
      <inertial>
        <pose>0 0 0 0 -0 0</pose>
        <mass>0.3</mass>
        <inertia>
          <ixx>0.001</ixx>
          <ixy>0</ixy>
          <ixz>0</ixz>
          <iyy>0.001</iyy>
          <iyz>0</iyz>
          <izz>0.001</izz>
        </inertia>
      </inertial>
      <collision name="left_caster_wheel_link_collision">
        <pose>0 0 0 0 -0 0</pose>
        <geometry>
          <sphere>
            <radius>0.05</radius>
          </sphere>
        </geometry>
        <surface>
          <contact><ode/></contact>
          <friction>
            <ode>
              <mu>0.8</mu>
              <mu2>0.8</mu2>
            </ode>
          </friction>
        </surface>
      </collision>
      <visual name="left_caster_wheel_link_visual">
        <pose>0 0 0 0 -0 0</pose>
        <geometry>
          <sphere>
            <radius>0.05</radius>
          </sphere>
        </geometry>
        <material>
          <ambient>0.0 0.0 0.0 1</ambient>
          <diffuse>0.0 0.0 0.0 1</diffuse>
          <specular>0.1 0.1 0.1 1</specular>
          <emissive>0 0 0 1</emissive>
        </material>
      </visual>
    </link>

    <joint name="left_wheel_joint" type="revolute">
      <pose relative_to="base_footprint">0 0.23075 0.152 -1.5708 0 0</pose>
      <parent>base_footprint</parent>
      <child>left_wheel_link</child>
      <axis>
        <xyz>0 0 1</xyz>
        <limit>
          <effort>10.5</effort>
          <velocity>10</velocity>
          <lower>-1e+16</lower>
          <upper>1e+16</upper>
        </limit>
        <dynamics>
          <damping>0.05</damping>
          <friction>0</friction>
          <spring_reference>0</spring_reference>
          <spring_stiffness>0</spring_stiffness>
        </dynamics>
      </axis>
    </joint>

    <link name="left_wheel_link">
      <pose relative_to="left_wheel_joint">0 0 0 0 -0 0</pose>
      <inertial>
        <pose>0 0 0 0 -0 0</pose>
        <mass>0.15</mass>
        <inertia>
          <ixx>0.005</ixx>
          <ixy>0</ixy>
          <ixz>0</ixz>
          <iyy>0.005</iyy>
          <iyz>0</iyz>
          <izz>0.01</izz>
        </inertia>
      </inertial>
      <collision name="left_wheel_link_collision">
        <pose>0 0 0 0 -0 0</pose>
        <geometry>
          <cylinder>
            <length>0.045</length>
            <radius>0.152</radius>
          </cylinder>
        </geometry>
        <surface>
          <contact><ode/></contact>
          <friction>
            <ode>
              <mu>0.8</mu>
              <mu2>0.8</mu2>
            </ode>
          </friction>
        </surface>
      </collision>
      <visual name="left_wheel_link_visual">
        <pose>0 0 0 0 -0 0</pose>
        <geometry>
          <cylinder>
            <length>0.045</length>
            <radius>0.152</radius>
          </cylinder>
        </geometry>
        <material>
          <ambient>0.0 0.0 0.0 1</ambient>
          <diffuse>0.0 0.0 0.0 1</diffuse>
          <specular>0.1 0.1 0.1 1</specular>
          <emissive>0 0 0 1</emissive>
        </material>
      </visual>
    </link>

    <joint name="right_caster_ball_joint" type="ball">
      <pose relative_to="base_footprint">0.392 -0.15 0.05 0 -0 0</pose>
      <parent>base_footprint</parent>
      <child>right_caster_wheel_link</child>
    </joint>

    <link name="right_caster_wheel_link">
      <pose relative_to="right_caster_ball_joint">0 0 0 1.5708 0 0</pose>
      <inertial>
        <pose>0 0 0 0 -0 0</pose>
        <mass>0.3</mass>
        <inertia>
          <ixx>0.001</ixx>
          <ixy>0</ixy>
          <ixz>0</ixz>
          <iyy>0.001</iyy>
          <iyz>0</iyz>
          <izz>0.001</izz>
        </inertia>
      </inertial>
      <collision name="right_caster_wheel_link_collision">
        <pose>0 0 0 0 -0 0</pose>
        <geometry>
          <sphere>
            <radius>0.05</radius>
          </sphere>
        </geometry>
        <surface>
          <contact><ode/></contact>
          <friction>
            <ode>
              <mu>0.8</mu>
              <mu2>0.8</mu2>
            </ode>
          </friction>
        </surface>
      </collision>
      <visual name="right_caster_wheel_link_visual">
        <pose>0 0 0 0 -0 0</pose>
        <geometry>
          <sphere>
            <radius>0.05</radius>
          </sphere>
        </geometry>
        <material>
          <ambient>0.0 0.0 0.0 1</ambient>
          <diffuse>0.0 0.0 0.0 1</diffuse>
          <specular>0.1 0.1 0.1 1</specular>
          <emissive>0 0 0 1</emissive>
        </material>
      </visual>
    </link>

    <joint name="right_wheel_joint" type="revolute">
      <pose relative_to="base_footprint">0 -0.23075 0.152 -1.5708 0 0</pose>
      <parent>base_footprint</parent>
      <child>right_wheel_link</child>
      <axis>
        <xyz>0 0 1</xyz>
        <limit>
          <effort>10.5</effort>
          <velocity>10</velocity>
          <lower>-1e+16</lower>
          <upper>1e+16</upper>
        </limit>
        <dynamics>
          <damping>0.05</damping>
          <friction>0</friction>
          <spring_reference>0</spring_reference>
          <spring_stiffness>0</spring_stiffness>
        </dynamics>
      </axis>
    </joint>

    <link name="right_wheel_link">
      <pose relative_to="right_wheel_joint">0 0 0 0 -0 0</pose>
      <inertial>
        <pose>0 0 0 0 -0 0</pose>
        <mass>0.15</mass>
        <inertia>
          <ixx>0.005</ixx>
          <ixy>0</ixy>
          <ixz>0</ixz>
          <iyy>0.005</iyy>
          <iyz>0</iyz>
          <izz>0.01</izz>
        </inertia>
      </inertial>
      <collision name="right_wheel_link_collision">
        <pose>0 0 0 0 -0 0</pose>
        <geometry>
          <cylinder>
            <length>0.045</length>
            <radius>0.152</radius>
          </cylinder>
        </geometry>
        <surface>
          <contact><ode/></contact>
          <friction>
            <ode>
              <mu>0.8</mu>
              <mu2>0.8</mu2>
            </ode>
          </friction>
        </surface>
      </collision>
      <visual name="right_wheel_link_visual">
        <pose>0 0 0 0 -0 0</pose>
        <geometry>
          <cylinder>
            <length>0.045</length>
            <radius>0.152</radius>
          </cylinder>
        </geometry>
        <material>
          <ambient>0.0 0.0 0.0 1</ambient>
          <diffuse>0.0 0.0 0.0 1</diffuse>
          <specular>0.1 0.1 0.1 1</specular>
          <emissive>0 0 0 1</emissive>
        </material>
      </visual>
    </link>

    <plugin name="ignition::gazebo::systems::DiffDrive" filename="libignition-gazebo-diff-drive-system.so">
      <left_joint>left_wheel_joint</left_joint>
      <right_joint>right_wheel_joint</right_joint>
      <wheel_separation>0.4615</wheel_separation>
      <wheel_radius>0.145</wheel_radius>
      <odom_publish_frequency>30</odom_publish_frequency>
      <topic>cmd_vel</topic>
      <odom_topic>wheel_odom</odom_topic>
      <frame_id>odom</frame_id>
      <child_frame_id>base_footprint</child_frame_id>
    </plugin>

    <plugin name="ignition::gazebo::systems::OdometryPublisher" filename="libignition-gazebo-odometry-publisher-system.so">
      <odom_frame>rsf_odom</odom_frame>
      <robot_base_frame>rsf_hokuyo3d</robot_base_frame>
      <odom_publish_frequency>100</odom_publish_frequency>
      <odom_topic>odom</odom_topic>
      <dimensions>3</dimensions>
      <gaussian_noise>0.0</gaussian_noise>
    </plugin>

    <plugin name="ignition::gazebo::systems::Sensors" filename="ignition-gazebo-sensors-system">
      <render_engine>ogre2</render_engine>
    </plugin>

    <static>0</static>

  </model>
</sdf>
