<?xml version="1.0"?>
<robot xmlns:xacro="http://www.ros.org/wiki/xacro">
  <xacro:macro name="wheel" params="prefix parent *origin">
    <joint name="${prefix}_wheel_joint" type="continuous">
      <parent link="${parent}"/>
      <child link="${prefix}_wheel_link"/>
      <xacro:insert_block name="origin"/>
      <axis xyz="0 0 1"/>
      <dynamics damping="0.05" friction="0.0"/>
    </joint>

    <link name="${prefix}_wheel_link">
      <inertial>
        <origin xyz="0 0 0" rpy="0 0 0"/>
        <mass value="0.15"/>
        <inertia ixx="0.005" ixy="0" ixz="0"
                 iyy="0.005" iyz="0" izz="0.01"/>
      </inertial>
      <collision>
        <origin xyz="0 0 0" rpy="0 0 0"/>
        <geometry>
          <cylinder length="0.045" radius="0.152"/>
        </geometry>
      </collision>
      <visual>
        <origin xyz="0 0 0" rpy="0 0 0"/>
        <geometry>
          <cylinder length="0.045" radius="0.152"/>
        </geometry>
        <material name="wheel_black"/>
      </visual>
    </link>
  </xacro:macro>
</robot>
